Workbook

Sheet HYPNOBOX
A1: ÁREA: | B1: COMERCIAL
A2: PATROCINADOR | B2: MICHEL
A3: NA-TI | B3: DANIEL
A4: DATA | B4: 46055
A5: CITY | G5: porque a sua nota foi esta?
A7: ÁREA | B7: PROCESSO | C7: REQUISITO | D7: Descrição | E7: PESO | F7: DESCRIÇÃO PESO | G7: POSITIVO | H7: NEGATIVO | I7: NOTA
A8: GERAL | B8: EMPREENDIMENTO | C8: CADASTRO | D8: Realizar o cadastro dos dados relacionados ao empreendimento, como data de lançamento, número da RI, data de entrega, área, nome fantasia e razão social da empresa, endereço, posição geográfica, conta de pagamento, código do empreendimento no erp, amenidades, pontos fortes e afins. | E8: 5 | F8: =VLOOKUP(E8,REGRAS!$A$2:$B$6,2,FALSE) -> Eliminatório (Must-have) | G8: conseguimos cadastrar todas as informações necessários para os demais processos | H8: precisa ser feito pela hypnobox para garantir funcionamento | I8: 4
A9: GERAL | B9: EMPREENDIMENTO | C9: MATERIAL DE APOIO A VENDA | D9: Permite anexar ao empreendimento material que auxilie o processo de venda, como vídeos, imagens e scripts de venda, quebra de resistencia e afins. | E9: 1 | F9: =VLOOKUP(E9,REGRAS!$A$2:$B$6,2,FALSE) -> Baixo valor na compra (Nice-to-have) | H9: não possui capacidade de armazenar e fornecer material de suporte a venda | I9: 2
A10: GERAL | B10: EMPREENDIMENTO | C10: UHs/LOTE | D10: Cadastro das unidades/lotes com suas características (m2, andar, local e etc) | E10: 5 | F10: =VLOOKUP(E10,REGRAS!$A$2:$B$6,2,FALSE) -> Eliminatório (Must-have) | G10: Atende corretamente | I10: 5
A11: GERAL | B11: EMPREENDIMENTO | C11: UHs/LOTE>TAGS | D11: Opção de marcar unidades, como, promoção, decorada, cobertura ou outra tag desejada | E11: 2 | F11: =VLOOKUP(E11,REGRAS!$A$2:$B$6,2,FALSE) -> Desejável | G11: Possuí algo neste sentido mas não conseguimos utilizar | I11: 3
A12: GERAL | B12: EMPREENDIMENTO | C12: UHs/LOTE>AGLUTINADOR | D12: Permite unificar unidades avulsas em uma única unidade para a venda, incluso valor próprio | E12: 3 | F12: =VLOOKUP(E12,REGRAS!$A$2:$B$6,2,FALSE) -> Importante | H12: não é possível criar agregadores de unidades | I12: 0
A13: GERAL | B13: EMPREENDIMENTO | C13: UHs/LOTE>COMBO | D13: Permite aglutinar unidades apenas como sugestão de venda com valor próprio (desconto por volume) | E13: 3 | F13: =VLOOKUP(E13,REGRAS!$A$2:$B$6,2,FALSE) -> Importante | H13: não é possível criar agregadores de unidades | I13: 0
A14: GERAL | B14: EMPREENDIMENTO | C14: TABELA DE PREÇO>CADASTRO | D14: Cadastrar tabelas de preço para as unidades | E14: 5 | F14: =VLOOKUP(E14,REGRAS!$A$2:$B$6,2,FALSE) -> Eliminatório (Must-have) | G14: é possível realizar o cadastramento de quase todas os planos de venda/valores | H14: ainda não conseguiram garantir o funcionamento de financiamento próprio com 2 indices (incc + ipca) | I14: 4
A15: GERAL | B15: EMPREENDIMENTO | C15: TABELA DE PREÇO>ATUALIZAÇÃO MONETÁRIA | D15: Permite informar atualização monetária para atualização das tabelas de preço, inclusive, com regra de arredondamento e calendário de execução. | E15: 5 | F15: =VLOOKUP(E15,REGRAS!$A$2:$B$6,2,FALSE) -> Eliminatório (Must-have) | G15: Tem a possibilidade de aplicar um indice | H15: Não é possível realziar via API e é burocrática no sistema | I15: 3
A16: GERAL | B16: EMPREENDIMENTO | C16: TABELA DE PREÇO>EVOLUÇÃO DO PREÇO | D16: Permite verificar, para uma unidade, a evolução de preço ao longo do tempo | E16: 2 | F16: =VLOOKUP(E16,REGRAS!$A$2:$B$6,2,FALSE) -> Desejável | H16: Não possuí esta funcionalidade | I16: 0
A17: GERAL | B17: EMPREENDIMENTO | C17: TABELA DE PREÇO>EXCEÇÕES > AGLUTINADOR | D17: Permite cadastrar preço para unidades aglutinadas. | E17: 3 | F17: =VLOOKUP(E17,REGRAS!$A$2:$B$6,2,FALSE) -> Importante | H17: Não possuí esta funcionalidade | I17: 0
A18: GERAL | B18: EMPREENDIMENTO | C18: TABELA DE PREÇO>EXCEÇÕES > COMBO | D18: Permite cadastrar preço para unidades agrupadas no combo. | E18: 3 | F18: =VLOOKUP(E18,REGRAS!$A$2:$B$6,2,FALSE) -> Importante | H18: Não possuí esta funcionalidade | I18: 0
A19: GERAL | B19: EMPREENDIMENTO | C19: API INTEGRAÇÃO | D19: Integração das rotinas do empreendimento (cadastro, material de apoio a vendas, uhs, tabela de preço) via API | E19: 4 | F19: =VLOOKUP(E19,REGRAS!$A$2:$B$6,2,FALSE) -> Crítico para operação/adaptação | H19: não achamos um endpoint real para nenhuma das opções do Empreendimento | I19: 1
A20: GERAL | B20: STATUS UNIDADE | C20: CADASTRO | D20: Permite criar status além do padrão do sistema, permitindo controle de situações fora do esperado, como, por exemplo, suspensa aguardando decoração. | E20: 2 | F20: =VLOOKUP(E20,REGRAS!$A$2:$B$6,2,FALSE) -> Desejável | G20: Permite criar status avulso | I20: 5
A21: GERAL | B21: STATUS UNIDADE | C21: ESPELHO DE VENDA | D21: Deve permitir consulta aos status da unidade. | E21: 5 | F21: =VLOOKUP(E21,REGRAS!$A$2:$B$6,2,FALSE) -> Eliminatório (Must-have) | G21: Permite visualização do espelho formatado por andar | I21: 5
A22: GERAL | B22: STATUS UNIDADE | C22: ESPELHO DE VENDA>API | D22: Permite consultar o status das unidades através de API | E22: 4 | F22: =VLOOKUP(E22,REGRAS!$A$2:$B$6,2,FALSE) -> Crítico para operação/adaptação | G22: Permite através de adaptação, com alta complexidade no objeto de retorno | I22: 4
A23: GERAL | B23: STATUS UNIDADE | C23: ESPELHO DE VENDA>ACESSO EXTERNO | D23: Permite acesso externo, não logado, ao espelho de vendas | E23: 3 | F23: =VLOOKUP(E23,REGRAS!$A$2:$B$6,2,FALSE) -> Importante | G23: Permite através de link | I23: 5
A24: GERAL | B24: ACESSO | C24: USUÁRIOS | D24: Cadastro de usuários do sistema | E24: 5 | F24: =VLOOKUP(E24,REGRAS!$A$2:$B$6,2,FALSE) -> Eliminatório (Must-have) | G24: Possui cadastro de usuários | I24: 5
A25: GERAL | B25: ACESSO | C25: USUÁRIOS>INTEGRAÇÃO AD | D25: Permite integrar com o AD com filtro apenas para usuários pertencentes ao grupo "Nome do Sistema" | E25: 3 | F25: =VLOOKUP(E25,REGRAS!$A$2:$B$6,2,FALSE) -> Importante | H25: Não possuí integração com o AD | I25: 0
A26: GERAL | B26: ACESSO | C26: CARGOS/GRUPOS | D26: Permite agrupar usuários e suas permissões (Corretor, Gerente, Diretor) | E26: 4 | F26: =VLOOKUP(E26,REGRAS!$A$2:$B$6,2,FALSE) -> Crítico para operação/adaptação | G26: Possuí cargos e pemissionamento ligado ao cargo | I26: 5
A27: GERAL | B27: ACESSO | C27: EMPREENDIMENTOS | D27: Permite agrupar usuários a empreendimentos em grupos distintos | E27: 3 | F27: =VLOOKUP(E27,REGRAS!$A$2:$B$6,2,FALSE) -> Importante | G27: Possuí vinculo do usuário com o empreendimento | I27: 5
A28: GERAL | B28: ACESSO | C28: EXTERNOS>IMOBILIÁRIA | D28: Cadastrar as imobiliárias e as informações para contato (comercial, administrativo, financeiro) | E28: 3 | F28: =VLOOKUP(E28,REGRAS!$A$2:$B$6,2,FALSE) -> Importante | H28: Não possui cadastro de imobiliárias | I28: 0
A29: GERAL | B29: ACESSO | C29: EXTERNOS>IMOBILIÁRIA>GESTOR | D29: Permite vincular Usuários a Imobiliárias | E29: 3 | F29: =VLOOKUP(E29,REGRAS!$A$2:$B$6,2,FALSE) -> Importante | H29: Não possui cadastro de imobiliárias | I29: 0
A30: GERAL | B30: ACESSO | C30: EXTERNOS>IMOBILIÁRIA>VINCULO CORRETOR | D30: Rotina para veinculação de corretores a imobiliária (utilizando o contato/gestor para aprovação da soliticação de agregação feita pelo corretor | E30: 3 | F30: =VLOOKUP(E30,REGRAS!$A$2:$B$6,2,FALSE) -> Importante | H30: Não possui cadastro de imobiliárias | I30: 0
A31: GERAL | B31: ACESSO | C31: EXTERNOS>CORRETORES | D31: Autocadastro dos corretores e solicitação de ingresso em uma imobiliária | E31: 3 | F31: =VLOOKUP(E31,REGRAS!$A$2:$B$6,2,FALSE) -> Importante | H31: Não possui cadastro de corretores externos | I31: 0
A32: GERAL | B32: ACESSO | C32: EXTERNOS>API INTEGRAÇÃO | D32: Permite realizar ações junto a imobiliárias e corretores através de API | E32: 3 | F32: =VLOOKUP(E32,REGRAS!$A$2:$B$6,2,FALSE) -> Importante | H32: não existe correlação de gestores e imobiliárias | I32: 0
A33: RESERVA | B33: GERAL | C33: CADASTRO>REQUISIÇÃO | D33: Permite requisitar uma reserva avulsa para uma determinada unidade, armazenando dados de log | E33: 5 | F33: =VLOOKUP(E33,REGRAS!$A$2:$B$6,2,FALSE) -> Eliminatório (Must-have) | G33: Permite realizar troca de status de maneira avulsa | H33: Não há controle de tempo quando utilizada esta função | I33: 3
A34: RESERVA | B34: GERAL | C34: TROCA DE RESPONSÁVEL | D34: Permite, ao trocar ou suspender o responsável pela imobiliária vinculada, que as reservas vinculadas sejam redirecionadas para o novo gestor | E34: 2 | F34: =VLOOKUP(E34,REGRAS!$A$2:$B$6,2,FALSE) -> Desejável | H34: Não há controle de responsáveis pela reserva já que não há requisição de reserva | I34: 0
A35: RESERVA | B35: GERAL | C35: FILA | D35: Permite enfileirar as requisições de reserva por ordem de chegada, guardando informações de requisitante, data, imobiliária e responsável | E35: 5 | F35: =VLOOKUP(E35,REGRAS!$A$2:$B$6,2,FALSE) -> Eliminatório (Must-have) | H35: Não há controle de fila de reserva | I35: 0
A36: RESERVA | B36: GERAL | C36: TEMPO DE VIDA>VENCIMENTO | D36: Requisições de reserva aprovadas e ativas precisam de controle de tempo de vida e serem canceladas quando vencidas | E36: 4 | F36: =VLOOKUP(E36,REGRAS!$A$2:$B$6,2,FALSE) -> Crítico para operação/adaptação | G36: Há controle simples de tempo de vida, com parametro único, começando a contar no momento do cadastro, já que não há requisição ou fila | H36: O tempo continua correndo mesmo com uma proposta em análise, vencendo outra pessoa pode reservar mesmo com a outra proposta ativa. | I36: 2
A37: RESERVA | B37: GERAL | C37: TEMPO DE VIDA>EXTENSÃO | D37: Requisições de reserva aprovadas e ativas podem ter seu tempo de vencimento extendido | E37: 4 | F37: =VLOOKUP(E37,REGRAS!$A$2:$B$6,2,FALSE) -> Crítico para operação/adaptação | H37: não é possível extender o prazo de uma reserva. | I37: 0
A38: RESERVA | B38: GERAL | C38: APROVAÇÃO | D38: Requisições de reserva precisam ser aprovadas, mesmo que seja apenas quando forem a reserva "da vez" (fila) | E38: 4 | F38: =VLOOKUP(E38,REGRAS!$A$2:$B$6,2,FALSE) -> Crítico para operação/adaptação | H38: Não existe aprovação de reservas | I38: 0
A39: RESERVA | B39: GERAL | C39: APROVAÇÃO>MULTI-NÍVEL | D39: Possível, para certas filas, exigir mais de uma aprovação para aceitar uma reserva | E39: 2 | F39: =VLOOKUP(E39,REGRAS!$A$2:$B$6,2,FALSE) -> Desejável | H39: Não existe aprovação de reservas | I39: 0
A40: RESERVA | B40: GERAL | C40: API INTEGRAÇÃO | D40: Permitir a consulta, adição e aprovação de reservas por API | E40: 4 | F40: =VLOOKUP(E40,REGRAS!$A$2:$B$6,2,FALSE) -> Crítico para operação/adaptação | H40: Não existe integração. | I40: 0
A41: RESERVA | B41: DESAFIANTE | C41: CADASTRO | D41: Permite que a reserva atualmente em vigor seja desafiada, e, se o desafio for aprovado, o tempo para vencimento é reduzido e, caso expirado, a desafiante passa automaticamente para a primeira posição da fila. | E41: 2 | F41: =VLOOKUP(E41,REGRAS!$A$2:$B$6,2,FALSE) -> Desejável | H41: Não há controle de desafiante | I41: 0
...

Sheet RESULTADO HYPNOBOX
D2: MÉDIA DAS NOTAS
B3: 5 | D3: =AVERAGEIF(HYPNOBOX!E:E,B3,HYPNOBOX!I:I) -> 3.7647059
B4: 4 | D4: =AVERAGEIF(HYPNOBOX!E:E,B4,HYPNOBOX!I:I) -> 2.7
B5: 3 | D5: =AVERAGEIF(HYPNOBOX!E:E,B5,HYPNOBOX!I:I) -> 0.73529412 | E5: =COUNTIF(HYPNOBOX!E:E,3) -> 34 | F5: =D5*E5 -> 25
B6: 2 | D6: =AVERAGEIF(HYPNOBOX!E:E,B6,HYPNOBOX!I:I) -> 1.1538462 | E6: =COUNTIF(HYPNOBOX!E:E,2) -> 13 | F6: =D6*E6 -> 15
B7: 1 | D7: =AVERAGEIF(HYPNOBOX!E:E,B7,HYPNOBOX!I:I) -> 0.4 | E7: =COUNTIF(HYPNOBOX!E:E,1) -> 5 | F7: =D7*E7 -> 2
B8: Unificada 3, 2 e 1 | D8: =F8/E8 -> 0.80769231 | E8: =SUM(E5:E7) -> 52 | F8: =SUM(F5:F7) -> 42
B10: ELIMINIAÇÃO | E10: nota de corte
B11: 5 | D11: =IF(COUNTIFS(HYPNOBOX!E:E,5,HYPNOBOX!I:I,"<"&E11)>0,"ELIMINADO","OK") -> ELIMINADO | E11: 4
B12: 4 | D12: =IF(COUNTIFS(HYPNOBOX!E:E,5,HYPNOBOX!I:I,"<"&E12)>0,"ELIMINADO","OK") -> ELIMINADO | E12: 3
B14: Nota Final
B15: 5 | C15: 0.6 | D15: =D3 -> 3.7647059 | E15: =C15*D15 -> 2.2588235
B16: 4 | C16: 0.3 | D16: =D4 -> 2.7 | E16: =C16*D16 -> 0.81
B17: 1,2,3 | C17: 0.1 | D17: =D8 -> 0.80769231 | E17: =C17*D17 -> 0.080769231
B19: NOTA FINAL | E19: =IF(OR(D11="ELIMINADO",D12="ELIMINADO"),0,SUM(E15:E17)) -> 0

Sheet REGRAS
A1: peso | B1: Avalia o quanto o requisito é importante para o negócio da City
A2: 5 | B2: Eliminatório (Must-have) | C2: Se não tiver de forma nativa ou comprovadamente atendida (configuração/módulo oficial), descarta o fornecedor. Sem isso, o sistema não atende o objetivo, compliance/segurança, ou o processo principal.
A3: 4 | B3: Crítico para operação/adaptação | C3: Se faltar, o risco de implantação e adoção sobe muito: muda processo demais, cria gargalo, aumenta erro, compromete controles. Só aceitável se o fornecedor resolver com configuração robusta, módulo oficial ou integração sólida (sem “promessa”).
A4: 3 | B4: Importante | C4: Entra forte na comparação entre fornecedores. Se faltar, gera custo/complexidade (customização, integrações, retrabalho) que precisa ser considerado no TCO, mas ainda pode ser viável comprar.
A5: 2 | B5: Desejável | C5: Traz ganho claro, mas não é decisivo. Se faltar, dá para conviver com ajuste de processo ou complemento leve.
A6: 1 | B6: Baixo valor na compra (Nice-to-have) | C6: Ajuda, mas não influencia a decisão. Pode ficar para “melhoria futura” ou solução paralela sem impacto.
A8: O que avaliar | B8: O que ter em mente no momento de dar a nota ao fornecedor quanto a um determinado requisito
A9: A | B9: Impacto no processo core (para o dia a dia rodar)
A10: B | B10: Risco (compliance, auditoria, segurança, fraude, LGPD, rastreabilidade)
A11: C | B11: Custo/complexidade de contorno (customização, integrações, operação manual)
A12: D | B12: Adoção (usuários conseguem trabalhar ou vão rejeitar)
A14: Notas | B14: Informa o quanto o fornecedor, olhando pelo prisma do que avaliar, atender o processo
A15: 5 | B15: Atende completamente
A16: 4 | B16: Atende quase tudo (lacunas pontuais) | C16: Atende o fluxo principal e a maioria dos cenários. Restam lacunas pontuais que não comprometem a operação, mas precisam ser tratadas (exceções específicas, detalhes de relatório/controle).
A17: 3 | B17: Atende parcialmente (operável com lacunas relevantes) | C17: O processo roda em parte, mas existem lacunas que exigem ajustes operacionais relevantes (exceções não cobertas, controles faltando, etapas críticas ausentes).
A18: 2 | B18: Atende muito pouco | C18: Cobre só partes isoladas, não sustenta o fluxo ponta a ponta do requisito. Falha em cenários comuns.
A19: 1 | B19: Não atende | C19: Não executa o processo necessário para aquele requisito (não passa no cenário mínimo).
C20: Cobre o requisito ponta a ponta, incluindo cenários principais e exceções relevantes, com os controles/saídas esperadas.
A22: Regras | B22: Racional | C22: Resultado
B23: Peso 5 com nota inferior a 3 (0 a 4) | C23: Desclassificado
B24: Peso 4 com nota inferior a 3 (0 a 4) | C24: Zera a nota
B25: Peso 3, 2 e 1 | C25: Mantém a nota
A27: Nota Final | C27: Nota classificação final
B28: 0,6 x Média(Nota5) + 0,3xMédia(Nota4) + 0,1*Média(Notas3,2,1)

Sheet REQUISITOS - BASE
A1: ÁREA: | B1: COMERCIAL
A2: PATROCINADOR | B2: MICHEL
A3: AN-TI | B3: DANIEL
A4: DATA
A5: CITY | G5: porque a sua nota foi esta?
A7: ÁREA | B7: PROCESSO | C7: REQUISITO | D7: Descrição | E7: PESO | F7: DESCRIÇÃO PESO | G7: POSITIVO | H7: NEGATIVO | I7: NOTA
A8: GERAL | B8: EMPREENDIMENTO | C8: CADASTRO | D8: Realizar o cadastro dos dados relacionados ao empreendimento, como data de lançamento, número da RI, data de entrega, área, nome fantasia e razão social da empresa, endereço, posição geográfica, conta de pagamento, código do empreendimento no erp, amenidades, pontos fortes e afins. | E8: 5 | F8: =VLOOKUP(E8,REGRAS!$A$2:$B$6,2,FALSE) -> Eliminatório (Must-have)
A9: GERAL | B9: EMPREENDIMENTO | C9: MATERIAL DE APOIO A VENDA | D9: Permite anexar ao empreendimento material que auxilie o processo de venda, como vídeos, imagens e scripts de venda, quebra de resistencia e afins. | E9: 1 | F9: =VLOOKUP(E9,REGRAS!$A$2:$B$6,2,FALSE) -> Baixo valor na compra (Nice-to-have)
A10: GERAL | B10: EMPREENDIMENTO | C10: UHs/LOTE | D10: Cadastro das unidades/lotes com suas características (m2, andar, local e etc) | E10: 5 | F10: =VLOOKUP(E10,REGRAS!$A$2:$B$6,2,FALSE) -> Eliminatório (Must-have)
A11: GERAL | B11: EMPREENDIMENTO | C11: UHs/LOTE>TAGS | D11: Opção de marcar unidades, como, promoção, decorada, cobertura ou outra tag desejada | E11: 2 | F11: =VLOOKUP(E11,REGRAS!$A$2:$B$6,2,FALSE) -> Desejável
A12: GERAL | B12: EMPREENDIMENTO | C12: UHs/LOTE>AGLUTINADOR | D12: Permite unificar unidades avulsas em uma única unidade para a venda, incluso valor próprio | E12: 3 | F12: =VLOOKUP(E12,REGRAS!$A$2:$B$6,2,FALSE) -> Importante
A13: GERAL | B13: EMPREENDIMENTO | C13: UHs/LOTE>COMBO | D13: Permite aglutinar unidades apenas como sugestão de venda com valor próprio (desconto por volume) | E13: 3 | F13: =VLOOKUP(E13,REGRAS!$A$2:$B$6,2,FALSE) -> Importante
A14: GERAL | B14: EMPREENDIMENTO | C14: TABELA DE PREÇO>CADASTRO | D14: Cadastrar tabelas de preço para as unidades | E14: 5 | F14: =VLOOKUP(E14,REGRAS!$A$2:$B$6,2,FALSE) -> Eliminatório (Must-have)
A15: GERAL | B15: EMPREENDIMENTO | C15: TABELA DE PREÇO>ATUALIZAÇÃO MONETÁRIA | D15: Permite informar atualização monetária para atualização das tabelas de preço, inclusive, com regra de arredondamento e calendário de execução. | E15: 5 | F15: =VLOOKUP(E15,REGRAS!$A$2:$B$6,2,FALSE) -> Eliminatório (Must-have)
A16: GERAL | B16: EMPREENDIMENTO | C16: TABELA DE PREÇO>EVOLUÇÃO DO PREÇO | D16: Permite verificar, para uma unidade, a evolução de preço ao longo do tempo | E16: 2 | F16: =VLOOKUP(E16,REGRAS!$A$2:$B$6,2,FALSE) -> Desejável
A17: GERAL | B17: EMPREENDIMENTO | C17: TABELA DE PREÇO>EXCEÇÕES > AGLUTINADOR | D17: Permite cadastrar preço para unidades aglutinadas. | E17: 3 | F17: =VLOOKUP(E17,REGRAS!$A$2:$B$6,2,FALSE) -> Importante
A18: GERAL | B18: EMPREENDIMENTO | C18: TABELA DE PREÇO>EXCEÇÕES > COMBO | D18: Permite cadastrar preço para unidades agrupadas no combo. | E18: 3 | F18: =VLOOKUP(E18,REGRAS!$A$2:$B$6,2,FALSE) -> Importante
A19: GERAL | B19: EMPREENDIMENTO | C19: API INTEGRAÇÃO | D19: Integração das rotinas do empreendimento (cadastro, material de apoio a vendas, uhs, tabela de preço) via API | E19: 4 | F19: =VLOOKUP(E19,REGRAS!$A$2:$B$6,2,FALSE) -> Crítico para operação/adaptação
... A94: CONTRATO | B94: NOTIFICAÇÕES | C94: LINK PORTAL | D94: Na notificação deve constar link que permita direcionamento direto para a ação ou informação vinculada | E94: 2 | F94: =VLOOKUP(E94,REGRAS!$A$2:$B$6,2,FALSE) -> Desejável
